Workbook

Sheet Dashboard
A1: GreetHub - Dashboard
A2: ="Scenario: "&Scenarios!B3&" (change on Scenarios sheet)" -> Scenario: Base (change on Scenarios sheet)
A3: Core KPIs below exclude the Kiosk and Agent programs. Side-by-side four-scenario comparison starts at row 52.
A4: KPI | B4: Value
A5: Break-even month (sustained) | B5: =Scenarios!$B$16 -> Not within 36 mo
A6: Cash payback month | B6: =Scenarios!$B$18 -> Not within 36 mo
A7: Month 12 net revenue | B7: =Scenarios!$B$19 -> 5358.0897
A8: Month 12 net income | B8: =Scenarios!$B$20 -> -5222.6607
A9: Month 36 net revenue | B9: =Scenarios!$B$21 -> 10226.959
A10: Month 36 net income | B10: =Scenarios!$B$22 -> -3115.9759
A11: Cash balance, month 36 | B11: =Scenarios!$B$27 -> -267461.65
A12: Peak funding need | B12: =Scenarios!$B$29 -> 297461.65
A13: Blended CAC | B13: =Scenarios!$B$31 -> 39.57446
A14: LTV per customer | B14: =Scenarios!$B$33 -> 25.834126
A15: LTV : blended CAC | B15: =Scenarios!$B$34 -> 0.65279796
A16: Orders, 36 months | B16: =Scenarios!$B$30 -> 9471.4107
A18: Annual summary | B18: Year 1 | C18: Year 2 | D18: Year 3
A19: Visits | B19: =Forecast!AO30 -> 156723.25 | C19: =Forecast!AP30 -> 192681.08 | D19: =Forecast!AQ30 -> 216934.53
A20: New-customer orders | B20: =Forecast!AO40 -> 1716.0527 | C20: =Forecast!AP40 -> 2130.2096 | D20: =Forecast!AQ40 -> 2412.2928
A21: Total orders | B21: =Forecast!AO43 -> 2007.4148 | C21: =Forecast!AP43 -> 3155.7292 | D21: =Forecast!AQ43 -> 4308.2667
A22: Net revenue | B22: =Forecast!AO60 -> 57322.61 | C22: =Forecast!AP60 -> 90113.233 | D22: =Forecast!AQ60 -> 123024.45
A23: Gross profit | B23: =Forecast!AO71 -> 27389.167 | C23: =Forecast!AP71 -> 44123.404 | D23: =Forecast!AQ71 -> 61155.744
A24: Marketing | B24: =Forecast!AO74 -> 82559.645 | C24: =Forecast!AP74 -> 82559.645 | D24: =Forecast!AQ74 -> 82559.645
A25: Operating costs | B25: =Forecast!AO75 -> 15007.28 | C25: =Forecast!AP75 -> 19251.011 | D25: =Forecast!AQ75 -> 20586.74
A26: Net income | B26: =Forecast!AO77 -> -197783.76 | C26: =Forecast!AP77 -> -57687.253 | D26: =Forecast!AQ77 -> -41990.642
A27: Ending cash | B27: =Forecast!AO80 -> -167783.76 | C27: =Forecast!AP80 -> -225471.01 | D27: =Forecast!AQ80 -> -267461.65
A29: Contribution margin per item | B29: CM $ | C29: CM %
A30: ='Unit Economics'!A5 -> Card - Digital e-card/PDF | B30: ='Unit Economics'!N5 -> 3.1930555 | C30: ='Unit Economics'!O5 -> 0.82501499
A31: ='Unit Economics'!A6 -> Card - Printed 5x7 folded | B31: ='Unit Economics'!N6 -> 4.4452865 | C31: ='Unit Economics'!O6 -> 0.4290581
A32: ='Unit Economics'!A7 -> Book - Digital flipbook/PDF | B32: ='Unit Economics'!N7 -> 17.176965 | C32: ='Unit Economics'!O7 -> 0.88585347
A33: ='Unit Economics'!A8 -> Book - Hardcover 8.5x8.5, 24pp | B33: ='Unit Economics'!N8 -> 21.418305 | C33: ='Unit Economics'!O8 -> 0.49741451
A34: ='Unit Economics'!A9 -> Book - Hardcover 8.5x8.5, 32pp | B34: ='Unit Economics'!N9 -> 27.836268 | C34: ='Unit Economics'!O9 -> 0.52760903
A52: Scenario comparison (36 months) | B52: Core only | C52: Core + Agent | D52: Core + Kiosk | E52: Everything
A53: Cumulative cash, month 12 | B53: =Compare!B52 -> -167783.76 | C53: =Compare!C52 -> -243297.94 | D53: =Compare!D52 -> -202398.76 | E53: =Compare!E52 -> -277912.94
A54: Cumulative cash, month 24 | B54: =Compare!B53 -> -225471.01 | C54: =Compare!C53 -> -313435.37 | D54: =Compare!D53 -> -260086.01 | E54: =Compare!E53 -> -348050.37
A55: Cumulative cash, month 36 | B55: =Compare!B54 -> -267461.65 | C55: =Compare!C54 -> -357652.27 | D55: =Compare!D54 -> -302076.65 | E55: =Compare!E54 -> -392267.27
A56: Peak funding need | B56: =Compare!B56 -> 297461.65 | C56: =Compare!C56 -> 387652.27 | D56: =Compare!D56 -> 332076.65 | E56: =Compare!E56 -> 422267.27
A57: Break-even month (sustained, net income) | B57: =Compare!B57 -> Not within 36 mo | C57: =Compare!C57 -> Not within 36 mo | D57: =Compare!D57 -> Not within 36 mo | E57: =Compare!E57 -> Not within 36 mo
A58: Total R&D spend | B58: =Compare!B58 -> 107100 | C58: =Compare!C58 -> 190800 | D58: =Compare!D58 -> 141715 | E58: =Compare!E58 -> 225415
A59: Cumulative net income | B59: =Compare!B59 -> -297461.65 | C59: =Compare!C59 -> -387652.27 | D59: =Compare!D59 -> -332076.65 | E59: =Compare!E59 -> -422267.27
...

Sheet Inputs
A1: GreetHub - Inputs (all business assumptions live here)
A2: Blue = input you can edit. Black = formula. Yellow fill = slot reserved for CMO/CTO data. Status: SOURCED / ESTIMATE / GUESS. Printer prices are ESTIMATES to verify against live Lulu / Prodigi / Gelato price sheets.
A3: Legend: | B3: Input | C3: Formula | D3: CMO / CTO data
A5: 1. General
A6: Assumption | B6: Value | C6: Unit | D6: Status | E6: Sensible range | F6: Notes / source
A7: Launch month (month 1) | B7: 46327 | C7: date | D7: SOURCED | E7: any | F7: CMO launch assumption: November 2026. Drives seasonality alignment.
A8: Opening cash (founder capital) | B8: 30000 | C8: $ | D8: GUESS | E8: $10k-100k | F8: Starting cash balance; also sets funding need.
A9: Items per paid order | B9: 1.15 | C9: items | D9: GUESS | E9: 1.0-1.5 | F9: Card+book bundles; Stripe $0.30 is per order, not per item.
A10: 2. Funnel (visitor -> sign-up -> creator start -> purchase)
A11: Assumption | B11: Value | C11: Unit | D11: Status | E11: Sensible range | F11: Notes / source
A12: Organic/referral visitor -> sign-up rate | B12: 0.07 | C12: % of visits | D12: GUESS | E12: 3%-12% | F12: Paid channels use per-channel CMO rates in section 7. Matches CMO range (4-9%).
A13: Sign-up -> creator start rate (all sources) | B13: 0.6 | C13: % of sign-ups | D13: GUESS | E13: 40%-80% | F13: Sign-ups who begin a brief; drives token cost of unpaid starts.
A14: Organic: creator start -> purchase rate | B14: 0.25 | C14: % of starts | D14: GUESS | E14: 12%-40% | F14: 0.60 x 0.25 = 15% sign-up -> purchase, in line with CMO channel rates (9-20%). Paid channels use CMO signup->purchase directly.
A15: Share of visitors who run a free guest preview | B15: 0.15 | C15: % of visits | D15: GUESS | E15: 5%-30% | F15: Guest previews cost tokens and earn no revenue (cost line in Forecast).
A16: Seasonality sensitivity of purchase conversion | B16: 0.5 | C16: 0-1 | D16: GUESS | E16: 0-1 | F16: 0 = season only changes traffic; 1 = conversion moves fully with season index.
A17: Token cost incurred before an unpaid creator start abandons | B17: 0.35 | C17: % of full cost | D17: ESTIMATE | E17: 20%-60% | F17: The model-sheet approval gate caps waste (PLAN.md).
A18: 3. Traffic
A19: Assumption | B19: Value | C19: Unit | D19: Status | E19: Sensible range | F19: Notes / source
A20: Organic visits, month 1 (before seasonality) | B20: 2000 | C20: visits | D20: GUESS | E20: 500-8,000 | F20: Brand/social/referral at launch.
A21: Organic monthly growth, month 2 | B21: 0.12 | C21: % / mo | D21: GUESS | E21: 5%-20% | F21: Compounds, then decays (next row).
A22: Organic growth decay factor per month | B22: 0.93 | C22: x | D22: GUESS | E22: 0.88-0.98 | F22: growth_t = g x decay^(t-1). 0.93 -> ~5x organic by month 36.
A23: Recipient referral visits per item sold (prior month) | B23: 0.3 | C23: visits/item | D23: GUESS | E23: 0.1-0.8 | F23: Card/book recipients open the 'made with GreetHub' link.
A24: 4. Marketing budget (paid visits = budget / CPC)
A25: Assumption | B25: Value | C25: Unit | D25: Status | E25: Sensible range | F25: Notes / source
A26: Monthly marketing budget, month 1 | B26: =SUM(B57:B62) -> 6500 | C26: $ / mo | D26: CMO PLAN (spend decision; CAC inputs mostly GUESS) | E26: $1k-15k | F26: Sum of CMO channel budgets (section 7), $6.5k/mo = $19.5k per 90 days. Overwrite with a number to test.
A27: Budget monthly growth | B27: 0 | C27: % / mo | D27: GUESS | E27: 0%-10% | F27: Compounds until cap. Growth only pays if contribution per order beats CAC.
A28: Budget cap | B28: 20000 | C28: $ / mo | D28: GUESS | E28: $5k-100k | F28: Ceiling on base monthly budget.
A29: Budget follows season index | B29: 0.5 | C29: 0-1 | D29: GUESS | E29: 0-1 | F29: 1 = budget scales fully with season index.
A30: 5. Repeat, refunds, re-rolls, payments
A31: Assumption | B31: Value | C31: Unit | D31: Status | E31: Sensible range | F31: Notes / source
A32: Repeat orders per existing customer per year | B32: 0.35 | C32: orders/yr | D32: GUESS | E32: 0.15-0.8 | F32: Occasion-driven; applied to cumulative customers.
A33: Customer lifetime used for LTV | B33: 2 | C33: years | D33: GUESS | E33: 1-3 | F33: LTV = contribution per order x (1 + repeat x lifetime).
A34: Re-roll rate, cards (extra renders over base) | B34: 0.2 | C34: % of renders | D34: GUESS (n=10) | E34: 20%-50% | F34: Only 10 first-attempt 2K page renders exist: 5/10 passed QA first time (95% CI 24-76%); 3 of the 5 fails were QA bugs since fixed (Model evals, 2026-10-12). Run 20% and 50%. Now flows through to measured token totals (Model Costs col J).
A35: Re-roll rate, books (extra renders over base) | B35: 0.2 | C35: % of renders | D35: GUESS (n=10) | E35: 20%-50% | F35: Only 10 first-attempt 2K page renders exist: 5/10 passed QA first time (95% CI 24-76%); 3 of the 5 fails were QA bugs since fixed (Model evals, 2026-10-12). Run 20% and 50%. Now flows through to measured token totals (Model Costs col J).
A36: Refund rate (share of revenue refunded) | B36: 0.03 | C36: % of revenue | D36: GUESS | E36: 1%-6% | F36: Token cost is sunk on refund.
A37: Reprint rate (printed items reshipped) | B37: 0.04 | C37: % of printed | D37: GUESS | E37: 2%-8% | F37: Print defects, transit damage. Costs print + shipping again.
A38: Chargeback rate | B38: 0.003 | C38: % of orders | D38: ESTIMATE | E38: 0.1%-1%
A39: Chargeback fee | B39: 15 | C39: $ / dispute | D39: SOURCED | E39: $15 | F39: Stripe dispute fee (US) - verify.
A40: Stripe fee, percentage | B40: 0.029 | C40: % of charge | D40: SOURCED | E40: 2.9% | F40: Owner brief / Stripe standard US card rate.
A41: Stripe fee, fixed | B41: 0.3 | C41: $ / order | D41: SOURCED | E41: $0.30 | F41: Owner brief / Stripe standard US card rate.
...

Sheet Scenarios
A1: Scenarios - selector drives the whole model
A3: Select scenario | B3: Base | C3: <- choose Low / Base / High (only control cell outside Inputs)
A4: Scenario index (1=Low, 2=Base, 3=High) | B4: =MATCH(B3,Inputs!$C$83:$E$83,0) -> 2
A6: Active lever | B6: Active value
A7: Organic traffic multiplier | B7: =INDEX(Inputs!$C$84:$E$84,$B$4) -> 1
A8: Purchase conversion multiplier | B8: =INDEX(Inputs!$C$85:$E$85,$B$4) -> 1
A9: Repeat purchase multiplier | B9: =INDEX(Inputs!$C$86:$E$86,$B$4) -> 1
A10: Token cost multiplier | B10: =INDEX(Inputs!$C$87:$E$87,$B$4) -> 1
A11: Refund / reprint multiplier | B11: =INDEX(Inputs!$C$88:$E$88,$B$4) -> 1
A12: Marketing budget multiplier | B12: =INDEX(Inputs!$C$89:$E$89,$B$4) -> 1
A13: Print + shipping cost multiplier | B13: =INDEX(Inputs!$C$90:$E$90,$B$4) -> 1
A15: Headline KPIs (selected scenario) | B15: Value | C15: Note
A16: Break-even month (sustained: trailing-3M profit stays >= 0) | B16: =IF(COUNT(Forecast!$D$85:$AM$85)=0,"Not within 36 mo",MIN(Forecast!$D$85:$AM$85)) -> Not within 36 mo | C16: Month # from launch
A17: First profitable month | B17: =IF(COUNT(Forecast!$D$84:$AM$84)=0,"Not within 36 mo",MIN(Forecast!$D$84:$AM$84)) -> Not within 36 mo | C17: May be a seasonal one-off
A18: Cash payback month (cumulative net income >= 0) | B18: =IF(COUNT(Forecast!$D$86:$AM$86)=0,"Not within 36 mo",MIN(Forecast!$D$86:$AM$86)) -> Not within 36 mo
A19: Month 12 net revenue | B19: =Forecast!O60 -> 5358.0897
A20: Month 12 net income | B20: =Forecast!O77 -> -5222.6607
A21: Month 36 net revenue | B21: =Forecast!AM60 -> 10226.959
A22: Month 36 net income | B22: =Forecast!AM77 -> -3115.9759
A23: Year 1 net revenue | B23: =Forecast!AO60 -> 57322.61
A24: Year 1 net income | B24: =Forecast!AO77 -> -197783.76
A25: Year 3 net revenue | B25: =Forecast!AQ60 -> 123024.45
A26: Year 3 net income | B26: =Forecast!AQ77 -> -41990.642
A27: Cash balance, month 36 | B27: =Forecast!AM80 -> -267461.65
A28: Lowest cash balance | B28: =MIN(Forecast!C80:AM80) -> -267461.65
A29: Peak funding need (opening cash minus lowest cash) | B29: =MAX(0,Inputs!$B$8-$B$28) -> 297461.65
A30: Total orders, 36 months | B30: =SUM(Forecast!$D$43:$AM$43) -> 9471.4107
A31: Blended CAC, 36 months ($ per new customer) | B31: =IFERROR(SUM(Forecast!$D$74:$AM$74)/SUM(Forecast!$D$40:$AM$40),0) -> 39.57446
A32: Paid CAC, steady state ($) | B32: ='Unit Economics'!$B$28 -> 70.375775
A33: LTV per customer (contribution $) | B33: ='Unit Economics'!$B$25 -> 25.834126
A34: LTV : blended CAC | B34: =IFERROR($B$33/$B$31,0) -> 0.65279796 | C34: Healthy >= 3x
A35: LTV : paid CAC | B35: =IFERROR($B$33/$B$32,0) -> 0.36708834
A36: Blended contribution margin per order ($) | B36: ='Unit Economics'!$B$23 -> 15.196545
A37: Gross margin, Year 3 | B37: =Forecast!AQ72 -> 0.49710236
A38: Guest preview cost, 36 months ($, no revenue) | B38: =SUM(Forecast!$D$63:$AM$63) -> 6175.0332
A41: Program and cost switches (v2). Second set of controls outside Inputs; blue cells with yellow fill are the only edit points.
A42: Include Kiosk program (0/1) | B42: 0 | C42: B42: adds the Kiosk sheet to the selected view. Off by default (kiosk/08). The Dashboard comparison always shows all four.
A43: Include Agent Channel (0/1) | B43: 0 | C43: B43: adds the Agent Channel sheet to the selected view.
A44: Market-adjusted (0/1) | B44: 0 | C44: B44: applies Inputs section 12 (Google CPC $4.14, free card postage at $8.99, digital book $14.99, books $44.99 / $54.99 all-in). Changes core results.
A45: Include v2 new cost lines (0/1) | B45: 1 | C45: B45: Inputs sections 13 and 14 (security, data, support, legal, insurance, accountant). Set 0 to see the original cost base.
...

Sheet Compare
A1: Compare - four scenarios by month (cumulative cash, net income, R&D)
A2: Core = Forecast (incl. v2 cost lines and core launch engineering per switches). Agent and Kiosk are the gross standalone streams. Selected = Scenarios switches B42/B43. Market-adjusted (B44) and Low/Base/High (B3) apply to every column.
A4: Line | B4: Unit | C4: Opening / total | D4: M1 | E4: M2 | F4: M3 | G4: M4 | H4: M5 | I4: M6 | J4: M7 | K4: M8 | L4: M9 | M4: M10 | N4: M11 | O4: M12 | P4: M13 | Q4: M14 | R4: M15 | S4: M16 | T4: M17 | U4: M18 | V4: M19 | W4: M20 | X4: M21 | Y4: M22 | Z4: M23 | AA4: M24 | AB4: M25 | AC4: M26 | AD4: M27 | AE4: M28 | AF4: M29 | AG4: M30 | AH4: M31 | AI4: M32 | AJ4: M33 | AK4: M34 | AL4: M35 | AM4: M36 | AN4: 36-mo total | AO4: Year 1 | AP4: Year 2 | AQ4: Year 3
A5: Month # | B5: # | D5: =Forecast!D6 -> 1 | E5: =Forecast!E6 -> 2 | F5: =Forecast!F6 -> 3 | G5: =Forecast!G6 -> 4 | H5: =Forecast!H6 -> 5 | I5: =Forecast!I6 -> 6 | J5: =Forecast!J6 -> 7 | K5: =Forecast!K6 -> 8 | ... AM5: =Forecast!AM6 -> 36
A6: STREAMS (net income unless noted)
A7: Core net income (Forecast row 77 = cash; no working capital) | B7: $ | D7: =Forecast!D77 -> -62740.91 | E7: =Forecast!E77 -> -54192.56 | F7: =Forecast!F77 -> -24287.991 | G7: =Forecast!G77 -> -12698.507 | H7: =Forecast!H77 -> -5564.125 | I7: =Forecast!I77 -> -5569.5702 | J7: =Forecast!J77 -> -5989.7197 | K7: =Forecast!K77 -> -5595.7554 | ... AM7: =Forecast!AM77 -> -3115.9759 | AN7: =SUM(D7:AM7) -> -297461.65 | AO7: =SUM(D7:O7) -> -197783.76 | AP7: =SUM(P7:AA7) -> -57687.253 | AQ7: =SUM(AB7:AM7) -> -41990.642
A8: Agent Channel net income = cash | B8: $ | D8: ='Agent Channel'!D38 -> -18000 | E8: ='Agent Channel'!E38 -> -11250 | F8: ='Agent Channel'!F38 -> -11250 | G8: ='Agent Channel'!G38 -> -8700 | H8: ='Agent Channel'!H38 -> -8700 | I8: ='Agent Channel'!I38 -> 0 | J8: ='Agent Channel'!J38 -> 0 | K8: ='Agent Channel'!K38 -> -293.95312 | ... AM8: ='Agent Channel'!AM38 -> -170.8087 | AN8: =SUM(D8:AM8) -> -90190.615 | AO8: =SUM(D8:O8) -> -75514.182 | AP8: =SUM(P8:AA8) -> -12450.174 | AQ8: =SUM(AB8:AM8) -> -2226.2591
A9: Kiosk net income (after depreciation) | B9: $ | D9: =Kiosk!D44 -> 0 | E9: =Kiosk!E44 -> 0 | F9: =Kiosk!F44 -> 0 | G9: =Kiosk!G44 -> 0 | H9: =Kiosk!H44 -> 0 | I9: =Kiosk!I44 -> 0 | J9: =Kiosk!J44 -> -11538.333 | K9: =Kiosk!K44 -> -11538.333 | ... AM9: =Kiosk!AM44 -> 0 | AN9: =SUM(D9:AM9) -> -34615 | AO9: =SUM(D9:O9) -> -34615 | AP9: =SUM(P9:AA9) -> 0 | AQ9: =SUM(AB9:AM9) -> 0
A10: Kiosk net cash flow (after capex) | B10: $ | D10: =Kiosk!D45 -> 0 | E10: =Kiosk!E45 -> 0 | F10: =Kiosk!F45 -> 0 | G10: =Kiosk!G45 -> 0 | H10: =Kiosk!H45 -> 0 | I10: =Kiosk!I45 -> 0 | J10: =Kiosk!J45 -> -11538.333 | K10: =Kiosk!K45 -> -11538.333 | ... AM10: =Kiosk!AM45 -> 0 | AN10: =SUM(D10:AM10) -> -34615 | AO10: =SUM(D10:O10) -> -34615 | AP10: =SUM(P10:AA10) -> 0 | AQ10: =SUM(AB10:AM10) -> 0
A11: R&D: core launch engineering in forecast | B11: $ | D11: ='R&D'!D13 -> 40650 | E11: ='R&D'!E13 -> 44130 | F11: ='R&D'!F13 -> 18840 | G11: ='R&D'!G13 -> 3480 | H11: ='R&D'!H13 -> 0 | I11: ='R&D'!I13 -> 0 | J11: ='R&D'!J13 -> 0 | K11: ='R&D'!K13 -> 0 | ... AM11: ='R&D'!AM13 -> 0 | AN11: =SUM(D11:AM11) -> 107100 | AO11: =SUM(D11:O11) -> 107100 | AP11: =SUM(P11:AA11) -> 0 | AQ11: =SUM(AB11:AM11) -> 0
A12: R&D: agent / AI-platform | B12: $ | D12: ='R&D'!D28 -> 18000 | E12: ='R&D'!E28 -> 11250 | F12: ='R&D'!F28 -> 11250 | G12: ='R&D'!G28 -> 8700 | H12: ='R&D'!H28 -> 8700 | I12: ='R&D'!I28 -> 0 | J12: ='R&D'!J28 -> 0 | K12: ='R&D'!K28 -> 0 | ... AM12: ='R&D'!AM28 -> 0 | AN12: =SUM(D12:AM12) -> 83700 | AO12: =SUM(D12:O12) -> 74100 | AP12: =SUM(P12:AA12) -> 9600 | AQ12: =SUM(AB12:AM12) -> 0
A13: R&D: kiosk program | B13: $ | D13: ='R&D'!D45 -> 0 | E13: ='R&D'!E45 -> 0 | F13: ='R&D'!F45 -> 0 | G13: ='R&D'!G45 -> 0 | H13: ='R&D'!H45 -> 0 | I13: ='R&D'!I45 -> 0 | J13: ='R&D'!J45 -> 11538.333 | K13: ='R&D'!K45 -> 11538.333 | ... AM13: ='R&D'!AM45 -> 0 | AN13: =SUM(D13:AM13) -> 34615 | AO13: =SUM(D13:O13) -> 34615 | AP13: =SUM(P13:AA13) -> 0 | AQ13: =SUM(AB13:AM13) -> 0
A14: SCENARIO: CORE ONLY
A15: Core only: net income | B15: $ | D15: =D7+0*D8+0*D9 -> -62740.91 | E15: =E7+0*E8+0*E9 -> -54192.56 | F15: =F7+0*F8+0*F9 -> -24287.991 | G15: =G7+0*G8+0*G9 -> -12698.507 | H15: =H7+0*H8+0*H9 -> -5564.125 | I15: =I7+0*I8+0*I9 -> -5569.5702 | J15: =J7+0*J8+0*J9 -> -5989.7197 | K15: =K7+0*K8+0*K9 -> -5595.7554 | ... AM15: =AM7+0*AM8+0*AM9 -> -3115.9759 | AN15: =SUM(D15:AM15) -> -297461.65 | AO15: =SUM(D15:O15) -> -197783.76 | AP15: =SUM(P15:AA15) -> -57687.253 | AQ15: =SUM(AB15:AM15) -> -41990.642
A16: Core only: net cash flow | B16: $ | D16: =D7+0*D8+0*D10 -> -62740.91 | E16: =E7+0*E8+0*E10 -> -54192.56 | F16: =F7+0*F8+0*F10 -> -24287.991 | G16: =G7+0*G8+0*G10 -> -12698.507 | H16: =H7+0*H8+0*H10 -> -5564.125 | I16: =I7+0*I8+0*I10 -> -5569.5702 | J16: =J7+0*J8+0*J10 -> -5989.7197 | K16: =K7+0*K8+0*K10 -> -5595.7554 | ... AM16: =AM7+0*AM8+0*AM10 -> -3115.9759 | AN16: =SUM(D16:AM16) -> -297461.65 | AO16: =SUM(D16:O16) -> -197783.76 | AP16: =SUM(P16:AA16) -> -57687.253 | AQ16: =SUM(AB16:AM16) -> -41990.642
A17: Core only: cumulative cash balance | B17: $ | C17: =Inputs!$B$8 -> 30000 | D17: =C17+D16 -> -32740.91 | E17: =D17+E16 -> -86933.47 | F17: =E17+F16 -> -111221.46 | G17: =F17+G16 -> -123919.97 | H17: =G17+H16 -> -129484.09 | I17: =H17+I16 -> -135053.66 | J17: =I17+J16 -> -141043.38 | K17: =J17+K16 -> -146639.14 | ... AM17: =AL17+AM16 -> -267461.65
A18: Core only: R&D spend | B18: $ | D18: =D11+0*D12+0*D13 -> 40650 | E18: =E11+0*E12+0*E13 -> 44130 | F18: =F11+0*F12+0*F13 -> 18840 | G18: =G11+0*G12+0*G13 -> 3480 | H18: =H11+0*H12+0*H13 -> 0 | I18: =I11+0*I12+0*I13 -> 0 | J18: =J11+0*J12+0*J13 -> 0 | K18: =K11+0*K12+0*K13 -> 0 | ... AM18: =AM11+0*AM12+0*AM13 -> 0 | AN18: =SUM(D18:AM18) -> 107100 | AO18: =SUM(D18:O18) -> 107100 | AP18: =SUM(P18:AA18) -> 0 | AQ18: =SUM(AB18:AM18) -> 0
A19: Core only: trailing 3-month net income | B19: $ | D19: =SUM(D15) -> -62740.91 | E19: =SUM(D15:E15) -> -116933.47 | F19: =SUM(D15:F15) -> -141221.46 | G19: =SUM(E15:G15) -> -91179.058 | H19: =SUM(F15:H15) -> -42550.623 | I19: =SUM(G15:I15) -> -23832.202 | J19: =SUM(H15:J15) -> -17123.415 | K19: =SUM(I15:K15) -> -17155.045 | L19: =SUM(J15:L15) -> -16917.997 | M19: =SUM(K15:M15) -> -16241.434 | ... AM19: =SUM(AK15:AM15) -> -9871.7615
A20: Core only: flag sustained break-even (all later T3M >= 0) | B20: month | D20: =IF(MIN(D19:$AM19)>=0,D$5,"") | E20: =IF(MIN(E19:$AM19)>=0,E$5,"") | F20: =IF(MIN(F19:$AM19)>=0,F$5,"") | G20: =IF(MIN(G19:$AM19)>=0,G$5,"") | H20: =IF(MIN(H19:$AM19)>=0,H$5,"") | I20: =IF(MIN(I19:$AM19)>=0,I$5,"") | J20: =IF(MIN(J19:$AM19)>=0,J$5,"") | K20: =IF(MIN(K19:$AM19)>=0,K$5,"") | ... AM20: =IF(MIN(AM19:$AM19)>=0,AM$5,"")
A21: SCENARIO: CORE + AGENT CHANNEL
A22: Core + Agent Channel: net income | B22: $ | D22: =D7+1*D8+0*D9 -> -80740.91 | E22: =E7+1*E8+0*E9 -> -65442.56 | F22: =F7+1*F8+0*F9 -> -35537.991 | G22: =G7+1*G8+0*G9 -> -21398.507 | H22: =H7+1*H8+0*H9 -> -14264.125 | I22: =I7+1*I8+0*I9 -> -5569.5702 | J22: =J7+1*J8+0*J9 -> -5989.7197 | K22: =K7+1*K8+0*K9 -> -5889.7086 | ... AM22: =AM7+1*AM8+0*AM9 -> -3286.7846 | AN22: =SUM(D22:AM22) -> -387652.27 | AO22: =SUM(D22:O22) -> -273297.94 | AP22: =SUM(P22:AA22) -> -70137.427 | AQ22: =SUM(AB22:AM22) -> -44216.901
A23: Core + Agent Channel: net cash flow | B23: $ | D23: =D7+1*D8+0*D10 -> -80740.91 | E23: =E7+1*E8+0*E10 -> -65442.56 | F23: =F7+1*F8+0*F10 -> -35537.991 | G23: =G7+1*G8+0*G10 -> -21398.507 | H23: =H7+1*H8+0*H10 -> -14264.125 | I23: =I7+1*I8+0*I10 -> -5569.5702 | J23: =J7+1*J8+0*J10 -> -5989.7197 | K23: =K7+1*K8+0*K10 -> -5889.7086 | ... AM23: =AM7+1*AM8+0*AM10 -> -3286.7846 | AN23: =SUM(D23:AM23) -> -387652.27 | AO23: =SUM(D23:O23) -> -273297.94 | AP23: =SUM(P23:AA23) -> -70137.427 | AQ23: =SUM(AB23:AM23) -> -44216.901
A24: Core + Agent Channel: cumulative cash balance | B24: $ | C24: =Inputs!$B$8 -> 30000 | D24: =C24+D23 -> -50740.91 | E24: =D24+E23 -> -116183.47 | F24: =E24+F23 -> -151721.46 | G24: =F24+G23 -> -173119.97 | H24: =G24+H23 -> -187384.09 | I24: =H24+I23 -> -192953.66 | J24: =I24+J23 -> -198943.38 | K24: =J24+K23 -> -204833.09 | ... AM24: =AL24+AM23 -> -357652.27
A25: Core + Agent Channel: R&D spend | B25: $ | D25: =D11+1*D12+0*D13 -> 58650 | E25: =E11+1*E12+0*E13 -> 55380 | F25: =F11+1*F12+0*F13 -> 30090 | G25: =G11+1*G12+0*G13 -> 12180 | H25: =H11+1*H12+0*H13 -> 8700 | I25: =I11+1*I12+0*I13 -> 0 | J25: =J11+1*J12+0*J13 -> 0 | K25: =K11+1*K12+0*K13 -> 0 | ... AM25: =AM11+1*AM12+0*AM13 -> 0 | AN25: =SUM(D25:AM25) -> 190800 | AO25: =SUM(D25:O25) -> 181200 | AP25: =SUM(P25:AA25) -> 9600 | AQ25: =SUM(AB25:AM25) -> 0
A26: Core + Agent Channel: trailing 3-month net income | B26: $ | D26: =SUM(D22) -> -80740.91 | E26: =SUM(D22:E22) -> -146183.47 | F26: =SUM(D22:F22) -> -181721.46 | G26: =SUM(E22:G22) -> -122379.06 | H26: =SUM(F22:H22) -> -71200.623 | I26: =SUM(G22:I22) -> -41232.202 | J26: =SUM(H22:J22) -> -25823.415 | K26: =SUM(I22:K22) -> -17448.998 | L26: =SUM(J22:L22) -> -23200.108 | M26: =SUM(K22:M22) -> -28506.15 | ... AM26: =SUM(AK22:AM22) -> -10391.205
A27: Core + Agent Channel: flag sustained break-even (all later T3M >= 0) | B27: month | D27: =IF(MIN(D26:$AM26)>=0,D$5,"") | E27: =IF(MIN(E26:$AM26)>=0,E$5,"") | F27: =IF(MIN(F26:$AM26)>=0,F$5,"") | G27: =IF(MIN(G26:$AM26)>=0,G$5,"") | H27: =IF(MIN(H26:$AM26)>=0,H$5,"") | I27: =IF(MIN(I26:$AM26)>=0,I$5,"") | J27: =IF(MIN(J26:$AM26)>=0,J$5,"") | K27: =IF(MIN(K26:$AM26)>=0,K$5,"") | ... AM27: =IF(MIN(AM26:$AM26)>=0,AM$5,"")
A28: SCENARIO: CORE + KIOSK
A29: Core + Kiosk: net income | B29: $ | D29: =D7+0*D8+1*D9 -> -62740.91 | E29: =E7+0*E8+1*E9 -> -54192.56 | F29: =F7+0*F8+1*F9 -> -24287.991 | G29: =G7+0*G8+1*G9 -> -12698.507 | H29: =H7+0*H8+1*H9 -> -5564.125 | I29: =I7+0*I8+1*I9 -> -5569.5702 | J29: =J7+0*J8+1*J9 -> -17528.053 | K29: =K7+0*K8+1*K9 -> -17134.089 | ... AM29: =AM7+0*AM8+1*AM9 -> -3115.9759 | AN29: =SUM(D29:AM29) -> -332076.65 | AO29: =SUM(D29:O29) -> -232398.76 | AP29: =SUM(P29:AA29) -> -57687.253 | AQ29: =SUM(AB29:AM29) -> -41990.642
A30: Core + Kiosk: net cash flow | B30: $ | D30: =D7+0*D8+1*D10 -> -62740.91 | E30: =E7+0*E8+1*E10 -> -54192.56 | F30: =F7+0*F8+1*F10 -> -24287.991 | G30: =G7+0*G8+1*G10 -> -12698.507 | H30: =H7+0*H8+1*H10 -> -5564.125 | I30: =I7+0*I8+1*I10 -> -5569.5702 | J30: =J7+0*J8+1*J10 -> -17528.053 | K30: =K7+0*K8+1*K10 -> -17134.089 | ... AM30: =AM7+0*AM8+1*AM10 -> -3115.9759 | AN30: =SUM(D30:AM30) -> -332076.65 | AO30: =SUM(D30:O30) -> -232398.76 | AP30: =SUM(P30:AA30) -> -57687.253 | AQ30: =SUM(AB30:AM30) -> -41990.642
A31: Core + Kiosk: cumulative cash balance | B31: $ | C31: =Inputs!$B$8 -> 30000 | D31: =C31+D30 -> -32740.91 | E31: =D31+E30 -> -86933.47 | F31: =E31+F30 -> -111221.46 | G31: =F31+G30 -> -123919.97 | H31: =G31+H30 -> -129484.09 | I31: =H31+I30 -> -135053.66 | J31: =I31+J30 -> -152581.72 | K31: =J31+K30 -> -169715.81 | ... AM31: =AL31+AM30 -> -302076.65
A32: Core + Kiosk: R&D spend | B32: $ | D32: =D11+0*D12+1*D13 -> 40650 | E32: =E11+0*E12+1*E13 -> 44130 | F32: =F11+0*F12+1*F13 -> 18840 | G32: =G11+0*G12+1*G13 -> 3480 | H32: =H11+0*H12+1*H13 -> 0 | I32: =I11+0*I12+1*I13 -> 0 | J32: =J11+0*J12+1*J13 -> 11538.333 | K32: =K11+0*K12+1*K13 -> 11538.333 | ... AM32: =AM11+0*AM12+1*AM13 -> 0 | AN32: =SUM(D32:AM32) -> 141715 | AO32: =SUM(D32:O32) -> 141715 | AP32: =SUM(P32:AA32) -> 0 | AQ32: =SUM(AB32:AM32) -> 0
A33: Core + Kiosk: trailing 3-month net income | B33: $ | D33: =SUM(D29) -> -62740.91 | E33: =SUM(D29:E29) -> -116933.47 | F33: =SUM(D29:F29) -> -141221.46 | G33: =SUM(E29:G29) -> -91179.058 | H33: =SUM(F29:H29) -> -42550.623 | I33: =SUM(G29:I29) -> -23832.202 | J33: =SUM(H29:J29) -> -28661.748 | K33: =SUM(I29:K29) -> -40231.712 | L33: =SUM(J29:L29) -> -51532.997 | M33: =SUM(K29:M29) -> -39318.1 | ... AM33: =SUM(AK29:AM29) -> -9871.7615
A34: Core + Kiosk: flag sustained break-even (all later T3M >= 0) | B34: month | D34: =IF(MIN(D33:$AM33)>=0,D$5,"") | E34: =IF(MIN(E33:$AM33)>=0,E$5,"") | F34: =IF(MIN(F33:$AM33)>=0,F$5,"") | G34: =IF(MIN(G33:$AM33)>=0,G$5,"") | H34: =IF(MIN(H33:$AM33)>=0,H$5,"") | I34: =IF(MIN(I33:$AM33)>=0,I$5,"") | J34: =IF(MIN(J33:$AM33)>=0,J$5,"") | K34: =IF(MIN(K33:$AM33)>=0,K$5,"") | ... AM34: =IF(MIN(AM33:$AM33)>=0,AM$5,"")
A35: SCENARIO: EVERYTHING
A36: Everything: net income | B36: $ | D36: =D7+1*D8+1*D9 -> -80740.91 | E36: =E7+1*E8+1*E9 -> -65442.56 | F36: =F7+1*F8+1*F9 -> -35537.991 | G36: =G7+1*G8+1*G9 -> -21398.507 | H36: =H7+1*H8+1*H9 -> -14264.125 | I36: =I7+1*I8+1*I9 -> -5569.5702 | J36: =J7+1*J8+1*J9 -> -17528.053 | K36: =K7+1*K8+1*K9 -> -17428.042 | ... AM36: =AM7+1*AM8+1*AM9 -> -3286.7846 | AN36: =SUM(D36:AM36) -> -422267.27 | AO36: =SUM(D36:O36) -> -307912.94 | AP36: =SUM(P36:AA36) -> -70137.427 | AQ36: =SUM(AB36:AM36) -> -44216.901
A37: Everything: net cash flow | B37: $ | D37: =D7+1*D8+1*D10 -> -80740.91 | E37: =E7+1*E8+1*E10 -> -65442.56 | F37: =F7+1*F8+1*F10 -> -35537.991 | G37: =G7+1*G8+1*G10 -> -21398.507 | H37: =H7+1*H8+1*H10 -> -14264.125 | I37: =I7+1*I8+1*I10 -> -5569.5702 | J37: =J7+1*J8+1*J10 -> -17528.053 | K37: =K7+1*K8+1*K10 -> -17428.042 | ... AM37: =AM7+1*AM8+1*AM10 -> -3286.7846 | AN37: =SUM(D37:AM37) -> -422267.27 | AO37: =SUM(D37:O37) -> -307912.94 | AP37: =SUM(P37:AA37) -> -70137.427 | AQ37: =SUM(AB37:AM37) -> -44216.901
A38: Everything: cumulative cash balance | B38: $ | C38: =Inputs!$B$8 -> 30000 | D38: =C38+D37 -> -50740.91 | E38: =D38+E37 -> -116183.47 | F38: =E38+F37 -> -151721.46 | G38: =F38+G37 -> -173119.97 | H38: =G38+H37 -> -187384.09 | I38: =H38+I37 -> -192953.66 | J38: =I38+J37 -> -210481.72 | K38: =J38+K37 -> -227909.76 | ... AM38: =AL38+AM37 -> -392267.27
A39: Everything: R&D spend | B39: $ | D39: =D11+1*D12+1*D13 -> 58650 | E39: =E11+1*E12+1*E13 -> 55380 | F39: =F11+1*F12+1*F13 -> 30090 | G39: =G11+1*G12+1*G13 -> 12180 | H39: =H11+1*H12+1*H13 -> 8700 | I39: =I11+1*I12+1*I13 -> 0 | J39: =J11+1*J12+1*J13 -> 11538.333 | K39: =K11+1*K12+1*K13 -> 11538.333 | ... AM39: =AM11+1*AM12+1*AM13 -> 0 | AN39: =SUM(D39:AM39) -> 225415 | AO39: =SUM(D39:O39) -> 215815 | AP39: =SUM(P39:AA39) -> 9600 | AQ39: =SUM(AB39:AM39) -> 0
A40: Everything: trailing 3-month net income | B40: $ | D40: =SUM(D36) -> -80740.91 | E40: =SUM(D36:E36) -> -146183.47 | F40: =SUM(D36:F36) -> -181721.46 | G40: =SUM(E36:G36) -> -122379.06 | H40: =SUM(F36:H36) -> -71200.623 | I40: =SUM(G36:I36) -> -41232.202 | J40: =SUM(H36:J36) -> -37361.748 | K40: =SUM(I36:K36) -> -40525.665 | L40: =SUM(J36:L36) -> -57815.108 | M40: =SUM(K36:M36) -> -51582.816 | ... AM40: =SUM(AK36:AM36) -> -10391.205
A41: Everything: flag sustained break-even (all later T3M >= 0) | B41: month | D41: =IF(MIN(D40:$AM40)>=0,D$5,"") | E41: =IF(MIN(E40:$AM40)>=0,E$5,"") | F41: =IF(MIN(F40:$AM40)>=0,F$5,"") | G41: =IF(MIN(G40:$AM40)>=0,G$5,"") | H41: =IF(MIN(H40:$AM40)>=0,H$5,"") | I41: =IF(MIN(I40:$AM40)>=0,I$5,"") | J41: =IF(MIN(J40:$AM40)>=0,J$5,"") | K41: =IF(MIN(K40:$AM40)>=0,K$5,"") | ... AM41: =IF(MIN(AM40:$AM40)>=0,AM$5,"")
...

Sheet R&D
A1: R&D - one-time and program engineering cost by month (36 months)
A2: Gross program cost, independent of the include switches. Core launch engineering flows into Forecast (switch Scenarios!B46); Agent and Kiosk programs flow only through Compare and the Dashboard. Change rate and days on Inputs sections 15-15c.
A4: Line | B4: Unit | C4: Person-days / total | D4: M1 | E4: M2 | F4: M3 | G4: M4 | H4: M5 | I4: M6 | J4: M7 | K4: M8 | L4: M9 | M4: M10 | N4: M11 | O4: M12 | P4: M13 | Q4: M14 | R4: M15 | S4: M16 | T4: M17 | U4: M18 | V4: M19 | W4: M20 | X4: M21 | Y4: M22 | Z4: M23 | AA4: M24 | AB4: M25 | AC4: M26 | AD4: M27 | AE4: M28 | AF4: M29 | AG4: M30 | AH4: M31 | AI4: M32 | AJ4: M33 | AK4: M34 | AL4: M35 | AM4: M36 | AN4: 36-mo total | AO4: Year 1 | AP4: Year 2 | AQ4: Year 3
A5: Month # | B5: # | D5: =Forecast!D6 -> 1 | E5: =Forecast!E6 -> 2 | F5: =Forecast!F6 -> 3 | G5: =Forecast!G6 -> 4 | H5: =Forecast!H6 -> 5 | I5: =Forecast!I6 -> 6 | J5: =Forecast!J6 -> 7 | K5: =Forecast!K6 -> 8 | ... AM5: =Forecast!AM6 -> 36
A6: (a) CORE LAUNCH ENGINEERING (remaining app work; days from the backlogs' own ticket sizes)
A7: =Inputs!A163 -> SEC MUST before launch (SEC-01 to 25) | B7: $ | C7: =Inputs!I163*(1+Inputs!$B$155) -> 47.4 | D7: =IF(AND(D$5>=Inputs!$J$163,D$5<Inputs!$J$163+Inputs!$K$163),Inputs!$I$163*(1+Inputs!$B$155)/Inputs!$K$163*Inputs!$B$152*Inputs!$B$154,0) -> 14220 | E7: =IF(AND(E$5>=Inputs!$J$163,E$5<Inputs!$J$163+Inputs!$K$163),Inputs!$I$163*(1+Inputs!$B$155)/Inputs!$K$163*Inputs!$B$152*Inputs!$B$154,0) -> 14220 | F7: =IF(AND(F$5>=Inputs!$J$163,F$5<Inputs!$J$163+Inputs!$K$163),Inputs!$I$163*(1+Inputs!$B$155)/Inputs!$K$163*Inputs!$B$152*Inputs!$B$154,0) -> 0 | G7: =IF(AND(G$5>=Inputs!$J$163,G$5<Inputs!$J$163+Inputs!$K$163),Inputs!$I$163*(1+Inputs!$B$155)/Inputs!$K$163*Inputs!$B$152*Inputs!$B$154,0) -> 0 | H7: =IF(AND(H$5>=Inputs!$J$163,H$5<Inputs!$J$163+Inputs!$K$163),Inputs!$I$163*(1+Inputs!$B$155)/Inputs!$K$163*Inputs!$B$152*Inputs!$B$154,0) -> 0 | I7: =IF(AND(I$5>=Inputs!$J$163,I$5<Inputs!$J$163+Inputs!$K$163),Inputs!$I$163*(1+Inputs!$B$155)/Inputs!$K$163*Inputs!$B$152*Inputs!$B$154,0) -> 0 | J7: =IF(AND(J$5>=Inputs!$J$163,J$5<Inputs!$J$163+Inputs!$K$163),Inputs!$I$163*(1+Inputs!$B$155)/Inputs!$K$163*Inputs!$B$152*Inputs!$B$154,0) -> 0 | K7: =IF(AND(K$5>=Inputs!$J$163,K$5<Inputs!$J$163+Inputs!$K$163),Inputs!$I$163*(1+Inputs!$B$155)/Inputs!$K$163*Inputs!$B$152*Inputs!$B$154,0) -> 0 | ... AM7: =IF(AND(AM$5>=Inputs!$J$163,AM$5<Inputs!$J$163+Inputs!$K$163),Inputs!$I$163*(1+Inputs!$B$155)/Inputs!$K$163*Inputs!$B$152*Inputs!$B$154,0) -> 0 | AN7: =SUM(D7:AM7) -> 28440 | AO7: =SUM(D7:O7) -> 28440 | AP7: =SUM(P7:AA7) -> 0 | AQ7: =SUM(AB7:AM7) -> 0
A8: =Inputs!A164 -> SEC AFTER launch (SEC-30 to 40) | B8: $ | C8: =Inputs!I164*(1+Inputs!$B$155) -> 17.4 | D8: =IF(AND(D$5>=Inputs!$J$164,D$5<Inputs!$J$164+Inputs!$K$164),Inputs!$I$164*(1+Inputs!$B$155)/Inputs!$K$164*Inputs!$B$152*Inputs!$B$154,0) -> 0 | E8: =IF(AND(E$5>=Inputs!$J$164,E$5<Inputs!$J$164+Inputs!$K$164),Inputs!$I$164*(1+Inputs!$B$155)/Inputs!$K$164*Inputs!$B$152*Inputs!$B$154,0) -> 3480 | F8: =IF(AND(F$5>=Inputs!$J$164,F$5<Inputs!$J$164+Inputs!$K$164),Inputs!$I$164*(1+Inputs!$B$155)/Inputs!$K$164*Inputs!$B$152*Inputs!$B$154,0) -> 3480 | G8: =IF(AND(G$5>=Inputs!$J$164,G$5<Inputs!$J$164+Inputs!$K$164),Inputs!$I$164*(1+Inputs!$B$155)/Inputs!$K$164*Inputs!$B$152*Inputs!$B$154,0) -> 3480 | H8: =IF(AND(H$5>=Inputs!$J$164,H$5<Inputs!$J$164+Inputs!$K$164),Inputs!$I$164*(1+Inputs!$B$155)/Inputs!$K$164*Inputs!$B$152*Inputs!$B$154,0) -> 0 | I8: =IF(AND(I$5>=Inputs!$J$164,I$5<Inputs!$J$164+Inputs!$K$164),Inputs!$I$164*(1+Inputs!$B$155)/Inputs!$K$164*Inputs!$B$152*Inputs!$B$154,0) -> 0 | J8: =IF(AND(J$5>=Inputs!$J$164,J$5<Inputs!$J$164+Inputs!$K$164),Inputs!$I$164*(1+Inputs!$B$155)/Inputs!$K$164*Inputs!$B$152*Inputs!$B$154,0) -> 0 | K8: =IF(AND(K$5>=Inputs!$J$164,K$5<Inputs!$J$164+Inputs!$K$164),Inputs!$I$164*(1+Inputs!$B$155)/Inputs!$K$164*Inputs!$B$152*Inputs!$B$154,0) -> 0 | ... AM8: =IF(AND(AM$5>=Inputs!$J$164,AM$5<Inputs!$J$164+Inputs!$K$164),Inputs!$I$164*(1+Inputs!$B$155)/Inputs!$K$164*Inputs!$B$152*Inputs!$B$154,0) -> 0 | AN8: =SUM(D8:AM8) -> 10440 | AO8: =SUM(D8:O8) -> 10440 | AP8: =SUM(P8:AA8) -> 0 | AQ8: =SUM(AB8:AM8) -> 0
A9: =Inputs!A165 -> Data backlog, must-have before launch (DATA-001 to 020) | B9: $ | C9: =Inputs!I165*(1+Inputs!$B$155) -> 64.8 | D9: =IF(AND(D$5>=Inputs!$J$165,D$5<Inputs!$J$165+Inputs!$K$165),Inputs!$I$165*(1+Inputs!$B$155)/Inputs!$K$165*Inputs!$B$152*Inputs!$B$154,0) -> 12960 | E9: =IF(AND(E$5>=Inputs!$J$165,E$5<Inputs!$J$165+Inputs!$K$165),Inputs!$I$165*(1+Inputs!$B$155)/Inputs!$K$165*Inputs!$B$152*Inputs!$B$154,0) -> 12960 | F9: =IF(AND(F$5>=Inputs!$J$165,F$5<Inputs!$J$165+Inputs!$K$165),Inputs!$I$165*(1+Inputs!$B$155)/Inputs!$K$165*Inputs!$B$152*Inputs!$B$154,0) -> 12960 | G9: =IF(AND(G$5>=Inputs!$J$165,G$5<Inputs!$J$165+Inputs!$K$165),Inputs!$I$165*(1+Inputs!$B$155)/Inputs!$K$165*Inputs!$B$152*Inputs!$B$154,0) -> 0 | H9: =IF(AND(H$5>=Inputs!$J$165,H$5<Inputs!$J$165+Inputs!$K$165),Inputs!$I$165*(1+Inputs!$B$155)/Inputs!$K$165*Inputs!$B$152*Inputs!$B$154,0) -> 0 | I9: =IF(AND(I$5>=Inputs!$J$165,I$5<Inputs!$J$165+Inputs!$K$165),Inputs!$I$165*(1+Inputs!$B$155)/Inputs!$K$165*Inputs!$B$152*Inputs!$B$154,0) -> 0 | J9: =IF(AND(J$5>=Inputs!$J$165,J$5<Inputs!$J$165+Inputs!$K$165),Inputs!$I$165*(1+Inputs!$B$155)/Inputs!$K$165*Inputs!$B$152*Inputs!$B$154,0) -> 0 | K9: =IF(AND(K$5>=Inputs!$J$165,K$5<Inputs!$J$165+Inputs!$K$165),Inputs!$I$165*(1+Inputs!$B$155)/Inputs!$K$165*Inputs!$B$152*Inputs!$B$154,0) -> 0 | ... AM9: =IF(AND(AM$5>=Inputs!$J$165,AM$5<Inputs!$J$165+Inputs!$K$165),Inputs!$I$165*(1+Inputs!$B$155)/Inputs!$K$165*Inputs!$B$152*Inputs!$B$154,0) -> 0 | AN9: =SUM(D9:AM9) -> 38880 | AO9: =SUM(D9:O9) -> 38880 | AP9: =SUM(P9:AA9) -> 0 | AQ9: =SUM(AB9:AM9) -> 0
A10: =Inputs!A166 -> CX must-fix before launch (CX-01 to 36) | B10: $ | C10: =Inputs!I166*(1+Inputs!$B$155) -> 36.9 | D10: =IF(AND(D$5>=Inputs!$J$166,D$5<Inputs!$J$166+Inputs!$K$166),Inputs!$I$166*(1+Inputs!$B$155)/Inputs!$K$166*Inputs!$B$152*Inputs!$B$154,0) -> 11070 | E10: =IF(AND(E$5>=Inputs!$J$166,E$5<Inputs!$J$166+Inputs!$K$166),Inputs!$I$166*(1+Inputs!$B$155)/Inputs!$K$166*Inputs!$B$152*Inputs!$B$154,0) -> 11070 | F10: =IF(AND(F$5>=Inputs!$J$166,F$5<Inputs!$J$166+Inputs!$K$166),Inputs!$I$166*(1+Inputs!$B$155)/Inputs!$K$166*Inputs!$B$152*Inputs!$B$154,0) -> 0 | G10: =IF(AND(G$5>=Inputs!$J$166,G$5<Inputs!$J$166+Inputs!$K$166),Inputs!$I$166*(1+Inputs!$B$155)/Inputs!$K$166*Inputs!$B$152*Inputs!$B$154,0) -> 0 | H10: =IF(AND(H$5>=Inputs!$J$166,H$5<Inputs!$J$166+Inputs!$K$166),Inputs!$I$166*(1+Inputs!$B$155)/Inputs!$K$166*Inputs!$B$152*Inputs!$B$154,0) -> 0 | I10: =IF(AND(I$5>=Inputs!$J$166,I$5<Inputs!$J$166+Inputs!$K$166),Inputs!$I$166*(1+Inputs!$B$155)/Inputs!$K$166*Inputs!$B$152*Inputs!$B$154,0) -> 0 | J10: =IF(AND(J$5>=Inputs!$J$166,J$5<Inputs!$J$166+Inputs!$K$166),Inputs!$I$166*(1+Inputs!$B$155)/Inputs!$K$166*Inputs!$B$152*Inputs!$B$154,0) -> 0 | K10: =IF(AND(K$5>=Inputs!$J$166,K$5<Inputs!$J$166+Inputs!$K$166),Inputs!$I$166*(1+Inputs!$B$155)/Inputs!$K$166*Inputs!$B$152*Inputs!$B$154,0) -> 0 | ... AM10: =IF(AND(AM$5>=Inputs!$J$166,AM$5<Inputs!$J$166+Inputs!$K$166),Inputs!$I$166*(1+Inputs!$B$155)/Inputs!$K$166*Inputs!$B$152*Inputs!$B$154,0) -> 0 | AN10: =SUM(D10:AM10) -> 22140 | AO10: =SUM(D10:O10) -> 22140 | AP10: =SUM(P10:AA10) -> 0 | AQ10: =SUM(AB10:AM10) -> 0
A11: =Inputs!A167 -> CTO integration, wiring, review and release (placeholder) | B11: $ | C11: =Inputs!I167*(1+Inputs!$B$155) -> 12 | D11: =IF(AND(D$5>=Inputs!$J$167,D$5<Inputs!$J$167+Inputs!$K$167),Inputs!$I$167*(1+Inputs!$B$155)/Inputs!$K$167*Inputs!$B$152*Inputs!$B$154,0) -> 2400 | E11: =IF(AND(E$5>=Inputs!$J$167,E$5<Inputs!$J$167+Inputs!$K$167),Inputs!$I$167*(1+Inputs!$B$155)/Inputs!$K$167*Inputs!$B$152*Inputs!$B$154,0) -> 2400 | F11: =IF(AND(F$5>=Inputs!$J$167,F$5<Inputs!$J$167+Inputs!$K$167),Inputs!$I$167*(1+Inputs!$B$155)/Inputs!$K$167*Inputs!$B$152*Inputs!$B$154,0) -> 2400 | G11: =IF(AND(G$5>=Inputs!$J$167,G$5<Inputs!$J$167+Inputs!$K$167),Inputs!$I$167*(1+Inputs!$B$155)/Inputs!$K$167*Inputs!$B$152*Inputs!$B$154,0) -> 0 | H11: =IF(AND(H$5>=Inputs!$J$167,H$5<Inputs!$J$167+Inputs!$K$167),Inputs!$I$167*(1+Inputs!$B$155)/Inputs!$K$167*Inputs!$B$152*Inputs!$B$154,0) -> 0 | I11: =IF(AND(I$5>=Inputs!$J$167,I$5<Inputs!$J$167+Inputs!$K$167),Inputs!$I$167*(1+Inputs!$B$155)/Inputs!$K$167*Inputs!$B$152*Inputs!$B$154,0) -> 0 | J11: =IF(AND(J$5>=Inputs!$J$167,J$5<Inputs!$J$167+Inputs!$K$167),Inputs!$I$167*(1+Inputs!$B$155)/Inputs!$K$167*Inputs!$B$152*Inputs!$B$154,0) -> 0 | K11: =IF(AND(K$5>=Inputs!$J$167,K$5<Inputs!$J$167+Inputs!$K$167),Inputs!$I$167*(1+Inputs!$B$155)/Inputs!$K$167*Inputs!$B$152*Inputs!$B$154,0) -> 0 | ... AM11: =IF(AND(AM$5>=Inputs!$J$167,AM$5<Inputs!$J$167+Inputs!$K$167),Inputs!$I$167*(1+Inputs!$B$155)/Inputs!$K$167*Inputs!$B$152*Inputs!$B$154,0) -> 0 | AN11: =SUM(D11:AM11) -> 7200 | AO11: =SUM(D11:O11) -> 7200 | AP11: =SUM(P11:AA11) -> 0 | AQ11: =SUM(AB11:AM11) -> 0
A12: Core launch engineering, gross | B12: $ | C12: =SUM(C7:C11) -> 178.5 | D12: =SUM(D7:D11) -> 40650 | E12: =SUM(E7:E11) -> 44130 | F12: =SUM(F7:F11) -> 18840 | G12: =SUM(G7:G11) -> 3480 | H12: =SUM(H7:H11) -> 0 | I12: =SUM(I7:I11) -> 0 | J12: =SUM(J7:J11) -> 0 | ... AM12: =SUM(AM7:AM11) -> 0 | AN12: =SUM(D12:AM12) -> 107100 | AO12: =SUM(D12:O12) -> 107100 | AP12: =SUM(P12:AA12) -> 0 | AQ12: =SUM(AB12:AM12) -> 0
A13: Core launch engineering in the forecast (after switch Scenarios!B46) | B13: $ | D13: =D12*Scenarios!$B$46 -> 40650 | E13: =E12*Scenarios!$B$46 -> 44130 | F13: =F12*Scenarios!$B$46 -> 18840 | G13: =G12*Scenarios!$B$46 -> 3480 | H13: =H12*Scenarios!$B$46 -> 0 | I13: =I12*Scenarios!$B$46 -> 0 | J13: =J12*Scenarios!$B$46 -> 0 | K13: =K12*Scenarios!$B$46 -> 0 | ... AM13: =AM12*Scenarios!$B$46 -> 0 | AN13: =SUM(D13:AM13) -> 107100 | AO13: =SUM(D13:O13) -> 107100 | AP13: =SUM(P13:AA13) -> 0 | AQ13: =SUM(AB13:AM13) -> 0
A15: (b) AGENT / AI-PLATFORM INTEGRATIONS (phases P0-P4 from the integrations plan; gates cascade)
A17: Effective gate to run P0 (1 = spent) | C17: =1 -> 1
A18: Effective gate to run P1 (1 = spent) | C18: =Inputs!$E$172 -> 1
A19: Effective gate to run P2 (1 = spent) | C19: =Inputs!$E$172*Inputs!$E$173 -> 1
A20: Effective gate to run P3 (1 = spent) | C20: =Inputs!$E$172*Inputs!$E$173*Inputs!$E$174 -> 1
A21: Effective gate to run P4 (1 = spent) | C21: =Inputs!$E$172*Inputs!$E$173*Inputs!$E$174*Inputs!$E$175 -> 1
A23: =Inputs!A171&" + attorney (agent addenda)" -> P0 new agent work (AGT-001 to 007) + attorney (agent addenda) | B23: $ | C23: =Inputs!B171 -> 20 | D23: =IF(AND(D$5>=Inputs!$C$171,D$5<Inputs!$C$171+Inputs!$D$171),(Inputs!$B$171*Inputs!$B$153*Inputs!$B$154+Inputs!$B$176)/Inputs!$D$171,0)*$C$17 -> 18000 | E23: =IF(AND(E$5>=Inputs!$C$171,E$5<Inputs!$C$171+Inputs!$D$171),(Inputs!$B$171*Inputs!$B$153*Inputs!$B$154+Inputs!$B$176)/Inputs!$D$171,0)*$C$17 -> 0 | F23: =IF(AND(F$5>=Inputs!$C$171,F$5<Inputs!$C$171+Inputs!$D$171),(Inputs!$B$171*Inputs!$B$153*Inputs!$B$154+Inputs!$B$176)/Inputs!$D$171,0)*$C$17 -> 0 | G23: =IF(AND(G$5>=Inputs!$C$171,G$5<Inputs!$C$171+Inputs!$D$171),(Inputs!$B$171*Inputs!$B$153*Inputs!$B$154+Inputs!$B$176)/Inputs!$D$171,0)*$C$17 -> 0 | H23: =IF(AND(H$5>=Inputs!$C$171,H$5<Inputs!$C$171+Inputs!$D$171),(Inputs!$B$171*Inputs!$B$153*Inputs!$B$154+Inputs!$B$176)/Inputs!$D$171,0)*$C$17 -> 0 | I23: =IF(AND(I$5>=Inputs!$C$171,I$5<Inputs!$C$171+Inputs!$D$171),(Inputs!$B$171*Inputs!$B$153*Inputs!$B$154+Inputs!$B$176)/Inputs!$D$171,0)*$C$17 -> 0 | J23: =IF(AND(J$5>=Inputs!$C$171,J$5<Inputs!$C$171+Inputs!$D$171),(Inputs!$B$171*Inputs!$B$153*Inputs!$B$154+Inputs!$B$176)/Inputs!$D$171,0)*$C$17 -> 0 | K23: =IF(AND(K$5>=Inputs!$C$171,K$5<Inputs!$C$171+Inputs!$D$171),(Inputs!$B$171*Inputs!$B$153*Inputs!$B$154+Inputs!$B$176)/Inputs!$D$171,0)*$C$17 -> 0 | ... AM23: =IF(AND(AM$5>=Inputs!$C$171,AM$5<Inputs!$C$171+Inputs!$D$171),(Inputs!$B$171*Inputs!$B$153*Inputs!$B$154+Inputs!$B$176)/Inputs!$D$171,0)*$C$17 -> 0 | AN23: =SUM(D23:AM23) -> 18000 | AO23: =SUM(D23:O23) -> 18000 | AP23: =SUM(P23:AA23) -> 0 | AQ23: =SUM(AB23:AM23) -> 0
A24: =Inputs!A172 -> P1 read and draft (AGT-010 to 019) | B24: $ | C24: =Inputs!B172 -> 37.5 | D24: =IF(AND(D$5>=Inputs!$C$172,D$5<Inputs!$C$172+Inputs!$D$172),(Inputs!$B$172*Inputs!$B$153*Inputs!$B$154)/Inputs!$D$172,0)*$C$18 -> 0 | E24: =IF(AND(E$5>=Inputs!$C$172,E$5<Inputs!$C$172+Inputs!$D$172),(Inputs!$B$172*Inputs!$B$153*Inputs!$B$154)/Inputs!$D$172,0)*$C$18 -> 11250 | F24: =IF(AND(F$5>=Inputs!$C$172,F$5<Inputs!$C$172+Inputs!$D$172),(Inputs!$B$172*Inputs!$B$153*Inputs!$B$154)/Inputs!$D$172,0)*$C$18 -> 11250 | G24: =IF(AND(G$5>=Inputs!$C$172,G$5<Inputs!$C$172+Inputs!$D$172),(Inputs!$B$172*Inputs!$B$153*Inputs!$B$154)/Inputs!$D$172,0)*$C$18 -> 0 | H24: =IF(AND(H$5>=Inputs!$C$172,H$5<Inputs!$C$172+Inputs!$D$172),(Inputs!$B$172*Inputs!$B$153*Inputs!$B$154)/Inputs!$D$172,0)*$C$18 -> 0 | I24: =IF(AND(I$5>=Inputs!$C$172,I$5<Inputs!$C$172+Inputs!$D$172),(Inputs!$B$172*Inputs!$B$153*Inputs!$B$154)/Inputs!$D$172,0)*$C$18 -> 0 | J24: =IF(AND(J$5>=Inputs!$C$172,J$5<Inputs!$C$172+Inputs!$D$172),(Inputs!$B$172*Inputs!$B$153*Inputs!$B$154)/Inputs!$D$172,0)*$C$18 -> 0 | K24: =IF(AND(K$5>=Inputs!$C$172,K$5<Inputs!$C$172+Inputs!$D$172),(Inputs!$B$172*Inputs!$B$153*Inputs!$B$154)/Inputs!$D$172,0)*$C$18 -> 0 | ... AM24: =IF(AND(AM$5>=Inputs!$C$172,AM$5<Inputs!$C$172+Inputs!$D$172),(Inputs!$B$172*Inputs!$B$153*Inputs!$B$154)/Inputs!$D$172,0)*$C$18 -> 0 | AN24: =SUM(D24:AM24) -> 22500 | AO24: =SUM(D24:O24) -> 22500 | AP24: =SUM(P24:AA24) -> 0 | AQ24: =SUM(AB24:AM24) -> 0
A25: =Inputs!A173 -> P2 approve and pay (AGT-020 to 027) | B25: $ | C25: =Inputs!B173 -> 29 | D25: =IF(AND(D$5>=Inputs!$C$173,D$5<Inputs!$C$173+Inputs!$D$173),(Inputs!$B$173*Inputs!$B$153*Inputs!$B$154)/Inputs!$D$173,0)*$C$19 -> 0 | E25: =IF(AND(E$5>=Inputs!$C$173,E$5<Inputs!$C$173+Inputs!$D$173),(Inputs!$B$173*Inputs!$B$153*Inputs!$B$154)/Inputs!$D$173,0)*$C$19 -> 0 | F25: =IF(AND(F$5>=Inputs!$C$173,F$5<Inputs!$C$173+Inputs!$D$173),(Inputs!$B$173*Inputs!$B$153*Inputs!$B$154)/Inputs!$D$173,0)*$C$19 -> 0 | G25: =IF(AND(G$5>=Inputs!$C$173,G$5<Inputs!$C$173+Inputs!$D$173),(Inputs!$B$173*Inputs!$B$153*Inputs!$B$154)/Inputs!$D$173,0)*$C$19 -> 8700 | H25: =IF(AND(H$5>=Inputs!$C$173,H$5<Inputs!$C$173+Inputs!$D$173),(Inputs!$B$173*Inputs!$B$153*Inputs!$B$154)/Inputs!$D$173,0)*$C$19 -> 8700 | I25: =IF(AND(I$5>=Inputs!$C$173,I$5<Inputs!$C$173+Inputs!$D$173),(Inputs!$B$173*Inputs!$B$153*Inputs!$B$154)/Inputs!$D$173,0)*$C$19 -> 0 | J25: =IF(AND(J$5>=Inputs!$C$173,J$5<Inputs!$C$173+Inputs!$D$173),(Inputs!$B$173*Inputs!$B$153*Inputs!$B$154)/Inputs!$D$173,0)*$C$19 -> 0 | K25: =IF(AND(K$5>=Inputs!$C$173,K$5<Inputs!$C$173+Inputs!$D$173),(Inputs!$B$173*Inputs!$B$153*Inputs!$B$154)/Inputs!$D$173,0)*$C$19 -> 0 | ... AM25: =IF(AND(AM$5>=Inputs!$C$173,AM$5<Inputs!$C$173+Inputs!$D$173),(Inputs!$B$173*Inputs!$B$153*Inputs!$B$154)/Inputs!$D$173,0)*$C$19 -> 0 | AN25: =SUM(D25:AM25) -> 17400 | AO25: =SUM(D25:O25) -> 17400 | AP25: =SUM(P25:AA25) -> 0 | AQ25: =SUM(AB25:AM25) -> 0
A26: =Inputs!A174&" (+ wallet if on)" -> P3 rules, keys, autonomy (AGT-030 to 034) (+ wallet if on) | B26: $ | C26: =Inputs!B174 -> 19 | D26: =IF(AND(D$5>=Inputs!$C$174,D$5<Inputs!$C$174+Inputs!$D$174),(Inputs!$B$174*Inputs!$B$153*Inputs!$B$154+Inputs!$B$178*Inputs!$B$177*Inputs!$B$153*Inputs!$B$154)/Inputs!$D$174,0)*$C$20 -> 0 | E26: =IF(AND(E$5>=Inputs!$C$174,E$5<Inputs!$C$174+Inputs!$D$174),(Inputs!$B$174*Inputs!$B$153*Inputs!$B$154+Inputs!$B$178*Inputs!$B$177*Inputs!$B$153*Inputs!$B$154)/Inputs!$D$174,0)*$C$20 -> 0 | F26: =IF(AND(F$5>=Inputs!$C$174,F$5<Inputs!$C$174+Inputs!$D$174),(Inputs!$B$174*Inputs!$B$153*Inputs!$B$154+Inputs!$B$178*Inputs!$B$177*Inputs!$B$153*Inputs!$B$154)/Inputs!$D$174,0)*$C$20 -> 0 | G26: =IF(AND(G$5>=Inputs!$C$174,G$5<Inputs!$C$174+Inputs!$D$174),(Inputs!$B$174*Inputs!$B$153*Inputs!$B$154+Inputs!$B$178*Inputs!$B$177*Inputs!$B$153*Inputs!$B$154)/Inputs!$D$174,0)*$C$20 -> 0 | H26: =IF(AND(H$5>=Inputs!$C$174,H$5<Inputs!$C$174+Inputs!$D$174),(Inputs!$B$174*Inputs!$B$153*Inputs!$B$154+Inputs!$B$178*Inputs!$B$177*Inputs!$B$153*Inputs!$B$154)/Inputs!$D$174,0)*$C$20 -> 0 | I26: =IF(AND(I$5>=Inputs!$C$174,I$5<Inputs!$C$174+Inputs!$D$174),(Inputs!$B$174*Inputs!$B$153*Inputs!$B$154+Inputs!$B$178*Inputs!$B$177*Inputs!$B$153*Inputs!$B$154)/Inputs!$D$174,0)*$C$20 -> 0 | J26: =IF(AND(J$5>=Inputs!$C$174,J$5<Inputs!$C$174+Inputs!$D$174),(Inputs!$B$174*Inputs!$B$153*Inputs!$B$154+Inputs!$B$178*Inputs!$B$177*Inputs!$B$153*Inputs!$B$154)/Inputs!$D$174,0)*$C$20 -> 0 | K26: =IF(AND(K$5>=Inputs!$C$174,K$5<Inputs!$C$174+Inputs!$D$174),(Inputs!$B$174*Inputs!$B$153*Inputs!$B$154+Inputs!$B$178*Inputs!$B$177*Inputs!$B$153*Inputs!$B$154)/Inputs!$D$174,0)*$C$20 -> 0 | ... AM26: =IF(AND(AM$5>=Inputs!$C$174,AM$5<Inputs!$C$174+Inputs!$D$174),(Inputs!$B$174*Inputs!$B$153*Inputs!$B$154+Inputs!$B$178*Inputs!$B$177*Inputs!$B$153*Inputs!$B$154)/Inputs!$D$174,0)*$C$20 -> 0 | AN26: =SUM(D26:AM26) -> 11400 | AO26: =SUM(D26:O26) -> 11400 | AP26: =SUM(P26:AA26) -> 0 | AQ26: =SUM(AB26:AM26) -> 0
A27: =Inputs!A175 -> P4 distribution / directory listings (AGT-040 to 045) | B27: $ | C27: =Inputs!B175 -> 24 | D27: =IF(AND(D$5>=Inputs!$C$175,D$5<Inputs!$C$175+Inputs!$D$175),(Inputs!$B$175*Inputs!$B$153*Inputs!$B$154)/Inputs!$D$175,0)*$C$21 -> 0 | E27: =IF(AND(E$5>=Inputs!$C$175,E$5<Inputs!$C$175+Inputs!$D$175),(Inputs!$B$175*Inputs!$B$153*Inputs!$B$154)/Inputs!$D$175,0)*$C$21 -> 0 | F27: =IF(AND(F$5>=Inputs!$C$175,F$5<Inputs!$C$175+Inputs!$D$175),(Inputs!$B$175*Inputs!$B$153*Inputs!$B$154)/Inputs!$D$175,0)*$C$21 -> 0 | G27: =IF(AND(G$5>=Inputs!$C$175,G$5<Inputs!$C$175+Inputs!$D$175),(Inputs!$B$175*Inputs!$B$153*Inputs!$B$154)/Inputs!$D$175,0)*$C$21 -> 0 | H27: =IF(AND(H$5>=Inputs!$C$175,H$5<Inputs!$C$175+Inputs!$D$175),(Inputs!$B$175*Inputs!$B$153*Inputs!$B$154)/Inputs!$D$175,0)*$C$21 -> 0 | I27: =IF(AND(I$5>=Inputs!$C$175,I$5<Inputs!$C$175+Inputs!$D$175),(Inputs!$B$175*Inputs!$B$153*Inputs!$B$154)/Inputs!$D$175,0)*$C$21 -> 0 | J27: =IF(AND(J$5>=Inputs!$C$175,J$5<Inputs!$C$175+Inputs!$D$175),(Inputs!$B$175*Inputs!$B$153*Inputs!$B$154)/Inputs!$D$175,0)*$C$21 -> 0 | K27: =IF(AND(K$5>=Inputs!$C$175,K$5<Inputs!$C$175+Inputs!$D$175),(Inputs!$B$175*Inputs!$B$153*Inputs!$B$154)/Inputs!$D$175,0)*$C$21 -> 0 | ... AM27: =IF(AND(AM$5>=Inputs!$C$175,AM$5<Inputs!$C$175+Inputs!$D$175),(Inputs!$B$175*Inputs!$B$153*Inputs!$B$154)/Inputs!$D$175,0)*$C$21 -> 0 | AN27: =SUM(D27:AM27) -> 14400 | AO27: =SUM(D27:O27) -> 4800 | AP27: =SUM(P27:AA27) -> 9600 | AQ27: =SUM(AB27:AM27) -> 0
A28: Agent / AI-platform program R&D, gross | B28: $ | D28: =SUM(D23:D27) -> 18000 | E28: =SUM(E23:E27) -> 11250 | F28: =SUM(F23:F27) -> 11250 | G28: =SUM(G23:G27) -> 8700 | H28: =SUM(H23:H27) -> 8700 | I28: =SUM(I23:I27) -> 0 | J28: =SUM(J23:J27) -> 0 | K28: =SUM(K23:K27) -> 0 | ... AM28: =SUM(AM23:AM27) -> 0 | AN28: =SUM(D28:AM28) -> 83700 | AO28: =SUM(D28:O28) -> 74100 | AP28: =SUM(P28:AA28) -> 9600 | AQ28: =SUM(AB28:AM28) -> 0
A30: (c) KIOSK PROGRAM, PHASES P0-P4 (low / base / high follows the scenario selector; gates G0-G3 cascade)
A31: Phase summary (selected scenario) | B31: Gate eff. | C31: Labor $ | D31: Non-labor $ | E31: Contingency $ | F31: Phase total $ | G31: Spent $ (after gates)
A32: =Inputs!A182 -> P0 Concept validation | B32: =1 -> 1 | C32: =(Inputs!$B$182*Inputs!$H$189+Inputs!$C$182*Inputs!$H$190)*Inputs!$H$188 -> 26000 | D32: =INDEX(Inputs!$G$182:$I$182,Scenarios!$B$4) -> 4100 | E32: =(C32+D32)*INDEX(Inputs!$J$182:$L$182,Scenarios!$B$4) -> 4515 | F32: =C32+D32+E32 -> 34615 | G32: =F32*B32 -> 34615
A33: =Inputs!A183 -> P1 Pilot prototype | B33: =Inputs!$F$183 -> 0 | C33: =(Inputs!$B$183*Inputs!$H$189+Inputs!$C$183*Inputs!$H$190)*Inputs!$H$188 -> 187000 | D33: =INDEX(Inputs!$G$183:$I$183,Scenarios!$B$4) -> 38300 | E33: =(C33+D33)*INDEX(Inputs!$J$183:$L$183,Scenarios!$B$4) -> 45060 | F33: =C33+D33+E33 -> 270360 | G33: =F33*B33 -> 0
A34: =Inputs!A184 -> P2 Field pilot (1-3 sites) | B34: =Inputs!$F$183*Inputs!$F$184 -> 0 | C34: =(Inputs!$B$184*Inputs!$H$189+Inputs!$C$184*Inputs!$H$190)*Inputs!$H$188 -> 98600 | D34: =INDEX(Inputs!$G$184:$I$184,Scenarios!$B$4) -> 45900 | E34: =(C34+D34)*INDEX(Inputs!$J$184:$L$184,Scenarios!$B$4) -> 28900 | F34: =C34+D34+E34 -> 173400 | G34: =F34*B34 -> 0
A35: =Inputs!A185 -> P3 Productized small batch | B35: =Inputs!$F$183*Inputs!$F$184*Inputs!$F$185 -> 0 | C35: =(Inputs!$B$185*Inputs!$H$189+Inputs!$C$185*Inputs!$H$190)*Inputs!$H$188 -> 200000 | D35: =INDEX(Inputs!$G$185:$I$185,Scenarios!$B$4) -> 106000 | E35: =(C35+D35)*INDEX(Inputs!$J$185:$L$185,Scenarios!$B$4) -> 61200 | F35: =C35+D35+E35 -> 367200 | G35: =F35*B35 -> 0
A36: =Inputs!A186 -> P4 Scale (sustaining) | B36: =Inputs!$F$183*Inputs!$F$184*Inputs!$F$185*Inputs!$F$186 -> 0 | C36: =(Inputs!$B$186*Inputs!$H$189+Inputs!$C$186*Inputs!$H$190)*Inputs!$H$188 -> 160000 | D36: =INDEX(Inputs!$G$186:$I$186,Scenarios!$B$4) -> 53000 | E36: =(C36+D36)*INDEX(Inputs!$J$186:$L$186,Scenarios!$B$4) -> 42600 | F36: =C36+D36+E36 -> 255600 | G36: =F36*B36 -> 0
A37: Total (ties to kiosk/08: $561k low, $1,101k base, $2,248k high when all gates pass) | F37: =SUM(F32:F36) -> 1101175 | G37: =SUM(G32:G36) -> 34615
A40: =Inputs!A182 -> P0 Concept validation | B40: $ | C40: =(Inputs!B182+Inputs!C182)*Inputs!$H$188 -> 26 | D40: =IF(AND(D$5>=Inputs!$D$182,D$5<Inputs!$D$182+Inputs!$E$182),$G$32/Inputs!$E$182,0) -> 0 | E40: =IF(AND(E$5>=Inputs!$D$182,E$5<Inputs!$D$182+Inputs!$E$182),$G$32/Inputs!$E$182,0) -> 0 | F40: =IF(AND(F$5>=Inputs!$D$182,F$5<Inputs!$D$182+Inputs!$E$182),$G$32/Inputs!$E$182,0) -> 0 | G40: =IF(AND(G$5>=Inputs!$D$182,G$5<Inputs!$D$182+Inputs!$E$182),$G$32/Inputs!$E$182,0) -> 0 | H40: =IF(AND(H$5>=Inputs!$D$182,H$5<Inputs!$D$182+Inputs!$E$182),$G$32/Inputs!$E$182,0) -> 0 | I40: =IF(AND(I$5>=Inputs!$D$182,I$5<Inputs!$D$182+Inputs!$E$182),$G$32/Inputs!$E$182,0) -> 0 | J40: =IF(AND(J$5>=Inputs!$D$182,J$5<Inputs!$D$182+Inputs!$E$182),$G$32/Inputs!$E$182,0) -> 11538.333 | K40: =IF(AND(K$5>=Inputs!$D$182,K$5<Inputs!$D$182+Inputs!$E$182),$G$32/Inputs!$E$182,0) -> 11538.333 | ... AM40: =IF(AND(AM$5>=Inputs!$D$182,AM$5<Inputs!$D$182+Inputs!$E$182),$G$32/Inputs!$E$182,0) -> 0 | AN40: =SUM(D40:AM40) -> 34615 | AO40: =SUM(D40:O40) -> 34615 | AP40: =SUM(P40:AA40) -> 0 | AQ40: =SUM(AB40:AM40) -> 0
A41: =Inputs!A183 -> P1 Pilot prototype | B41: $ | C41: =(Inputs!B183+Inputs!C183)*Inputs!$H$188 -> 187 | D41: =IF(AND(D$5>=Inputs!$D$183,D$5<Inputs!$D$183+Inputs!$E$183),$G$33/Inputs!$E$183,0) -> 0 | E41: =IF(AND(E$5>=Inputs!$D$183,E$5<Inputs!$D$183+Inputs!$E$183),$G$33/Inputs!$E$183,0) -> 0 | F41: =IF(AND(F$5>=Inputs!$D$183,F$5<Inputs!$D$183+Inputs!$E$183),$G$33/Inputs!$E$183,0) -> 0 | G41: =IF(AND(G$5>=Inputs!$D$183,G$5<Inputs!$D$183+Inputs!$E$183),$G$33/Inputs!$E$183,0) -> 0 | H41: =IF(AND(H$5>=Inputs!$D$183,H$5<Inputs!$D$183+Inputs!$E$183),$G$33/Inputs!$E$183,0) -> 0 | I41: =IF(AND(I$5>=Inputs!$D$183,I$5<Inputs!$D$183+Inputs!$E$183),$G$33/Inputs!$E$183,0) -> 0 | J41: =IF(AND(J$5>=Inputs!$D$183,J$5<Inputs!$D$183+Inputs!$E$183),$G$33/Inputs!$E$183,0) -> 0 | K41: =IF(AND(K$5>=Inputs!$D$183,K$5<Inputs!$D$183+Inputs!$E$183),$G$33/Inputs!$E$183,0) -> 0 | ... AM41: =IF(AND(AM$5>=Inputs!$D$183,AM$5<Inputs!$D$183+Inputs!$E$183),$G$33/Inputs!$E$183,0) -> 0 | AN41: =SUM(D41:AM41) -> 0 | AO41: =SUM(D41:O41) -> 0 | AP41: =SUM(P41:AA41) -> 0 | AQ41: =SUM(AB41:AM41) -> 0
A42: =Inputs!A184 -> P2 Field pilot (1-3 sites) | B42: $ | C42: =(Inputs!B184+Inputs!C184)*Inputs!$H$188 -> 113 | D42: =IF(AND(D$5>=Inputs!$D$184,D$5<Inputs!$D$184+Inputs!$E$184),$G$34/Inputs!$E$184,0) -> 0 | E42: =IF(AND(E$5>=Inputs!$D$184,E$5<Inputs!$D$184+Inputs!$E$184),$G$34/Inputs!$E$184,0) -> 0 | F42: =IF(AND(F$5>=Inputs!$D$184,F$5<Inputs!$D$184+Inputs!$E$184),$G$34/Inputs!$E$184,0) -> 0 | G42: =IF(AND(G$5>=Inputs!$D$184,G$5<Inputs!$D$184+Inputs!$E$184),$G$34/Inputs!$E$184,0) -> 0 | H42: =IF(AND(H$5>=Inputs!$D$184,H$5<Inputs!$D$184+Inputs!$E$184),$G$34/Inputs!$E$184,0) -> 0 | I42: =IF(AND(I$5>=Inputs!$D$184,I$5<Inputs!$D$184+Inputs!$E$184),$G$34/Inputs!$E$184,0) -> 0 | J42: =IF(AND(J$5>=Inputs!$D$184,J$5<Inputs!$D$184+Inputs!$E$184),$G$34/Inputs!$E$184,0) -> 0 | K42: =IF(AND(K$5>=Inputs!$D$184,K$5<Inputs!$D$184+Inputs!$E$184),$G$34/Inputs!$E$184,0) -> 0 | ... AM42: =IF(AND(AM$5>=Inputs!$D$184,AM$5<Inputs!$D$184+Inputs!$E$184),$G$34/Inputs!$E$184,0) -> 0 | AN42: =SUM(D42:AM42) -> 0 | AO42: =SUM(D42:O42) -> 0 | AP42: =SUM(P42:AA42) -> 0 | AQ42: =SUM(AB42:AM42) -> 0
A43: =Inputs!A185 -> P3 Productized small batch | B43: $ | C43: =(Inputs!B185+Inputs!C185)*Inputs!$H$188 -> 200 | D43: =IF(AND(D$5>=Inputs!$D$185,D$5<Inputs!$D$185+Inputs!$E$185),$G$35/Inputs!$E$185,0) -> 0 | E43: =IF(AND(E$5>=Inputs!$D$185,E$5<Inputs!$D$185+Inputs!$E$185),$G$35/Inputs!$E$185,0) -> 0 | F43: =IF(AND(F$5>=Inputs!$D$185,F$5<Inputs!$D$185+Inputs!$E$185),$G$35/Inputs!$E$185,0) -> 0 | G43: =IF(AND(G$5>=Inputs!$D$185,G$5<Inputs!$D$185+Inputs!$E$185),$G$35/Inputs!$E$185,0) -> 0 | H43: =IF(AND(H$5>=Inputs!$D$185,H$5<Inputs!$D$185+Inputs!$E$185),$G$35/Inputs!$E$185,0) -> 0 | I43: =IF(AND(I$5>=Inputs!$D$185,I$5<Inputs!$D$185+Inputs!$E$185),$G$35/Inputs!$E$185,0) -> 0 | J43: =IF(AND(J$5>=Inputs!$D$185,J$5<Inputs!$D$185+Inputs!$E$185),$G$35/Inputs!$E$185,0) -> 0 | K43: =IF(AND(K$5>=Inputs!$D$185,K$5<Inputs!$D$185+Inputs!$E$185),$G$35/Inputs!$E$185,0) -> 0 | ... AM43: =IF(AND(AM$5>=Inputs!$D$185,AM$5<Inputs!$D$185+Inputs!$E$185),$G$35/Inputs!$E$185,0) -> 0 | AN43: =SUM(D43:AM43) -> 0 | AO43: =SUM(D43:O43) -> 0 | AP43: =SUM(P43:AA43) -> 0 | AQ43: =SUM(AB43:AM43) -> 0
A44: =Inputs!A186 -> P4 Scale (sustaining) | B44: $ | C44: =(Inputs!B186+Inputs!C186)*Inputs!$H$188 -> 160 | D44: =IF(AND(D$5>=Inputs!$D$186,D$5<Inputs!$D$186+Inputs!$E$186),$G$36/Inputs!$E$186,0) -> 0 | E44: =IF(AND(E$5>=Inputs!$D$186,E$5<Inputs!$D$186+Inputs!$E$186),$G$36/Inputs!$E$186,0) -> 0 | F44: =IF(AND(F$5>=Inputs!$D$186,F$5<Inputs!$D$186+Inputs!$E$186),$G$36/Inputs!$E$186,0) -> 0 | G44: =IF(AND(G$5>=Inputs!$D$186,G$5<Inputs!$D$186+Inputs!$E$186),$G$36/Inputs!$E$186,0) -> 0 | H44: =IF(AND(H$5>=Inputs!$D$186,H$5<Inputs!$D$186+Inputs!$E$186),$G$36/Inputs!$E$186,0) -> 0 | I44: =IF(AND(I$5>=Inputs!$D$186,I$5<Inputs!$D$186+Inputs!$E$186),$G$36/Inputs!$E$186,0) -> 0 | J44: =IF(AND(J$5>=Inputs!$D$186,J$5<Inputs!$D$186+Inputs!$E$186),$G$36/Inputs!$E$186,0) -> 0 | K44: =IF(AND(K$5>=Inputs!$D$186,K$5<Inputs!$D$186+Inputs!$E$186),$G$36/Inputs!$E$186,0) -> 0 | ... AM44: =IF(AND(AM$5>=Inputs!$D$186,AM$5<Inputs!$D$186+Inputs!$E$186),$G$36/Inputs!$E$186,0) -> 0 | AN44: =SUM(D44:AM44) -> 0 | AO44: =SUM(D44:O44) -> 0 | AP44: =SUM(P44:AA44) -> 0 | AQ44: =SUM(AB44:AM44) -> 0
A45: Kiosk program R&D (expensed), gross | B45: $ | D45: =SUM(D40:D44) -> 0 | E45: =SUM(E40:E44) -> 0 | F45: =SUM(F40:F44) -> 0 | G45: =SUM(G40:G44) -> 0 | H45: =SUM(H40:H44) -> 0 | I45: =SUM(I40:I44) -> 0 | J45: =SUM(J40:J44) -> 11538.333 | K45: =SUM(K40:K44) -> 11538.333 | ... AM45: =SUM(AM40:AM44) -> 0 | AN45: =SUM(D45:AM45) -> 34615 | AO45: =SUM(D45:O45) -> 34615 | AP45: =SUM(P45:AA45) -> 0 | AQ45: =SUM(AB45:AM45) -> 0
A47: All program R&D, gross (core + agent + kiosk) | B47: $ | D47: =D12+D28+D45 -> 58650 | E47: =E12+E28+E45 -> 55380 | F47: =F12+F28+F45 -> 30090 | G47: =G12+G28+G45 -> 12180 | H47: =H12+H28+H45 -> 8700 | I47: =I12+I28+I45 -> 0 | J47: =J12+J28+J45 -> 11538.333 | K47: =K12+K28+K45 -> 11538.333 | ... AM47: =AM12+AM28+AM45 -> 0 | AN47: =SUM(D47:AM47) -> 225415 | AO47: =SUM(D47:O47) -> 215815 | AP47: =SUM(P47:AA47) -> 9600 | AQ47: =SUM(AB47:AM47) -> 0
A49: Timing note: costs within a phase are spread evenly. The kiosk doc front-loads prototype hardware and back-loads tooling inside a phase; phase totals and cumulative cash by phase end are unchanged.

Sheet Kiosk
A1: Kiosk - fleet build, unit economics and cash (Tier B freestanding)
A2: Gross standalone program view (independent of Scenarios!B42). Case follows the scenario selector. Phase gates and fleet plan are on Inputs sections 15c-16. All kiosk numbers are guesses until P2 field data (kiosk/08).
A4: Line | B4: Unit | C4: Total / opening | D4: M1 | E4: M2 | F4: M3 | G4: M4 | H4: M5 | I4: M6 | J4: M7 | K4: M8 | L4: M9 | M4: M10 | N4: M11 | O4: M12 | P4: M13 | Q4: M14 | R4: M15 | S4: M16 | T4: M17 | U4: M18 | V4: M19 | W4: M20 | X4: M21 | Y4: M22 | Z4: M23 | AA4: M24 | AB4: M25 | AC4: M26 | AD4: M27 | AE4: M28 | AF4: M29 | AG4: M30 | AH4: M31 | AI4: M32 | AJ4: M33 | AK4: M34 | AL4: M35 | AM4: M36 | AN4: 36-mo total | AO4: Year 1 | AP4: Year 2 | AQ4: Year 3
A5: Month # | B5: # | D5: =Forecast!D6 -> 1 | E5: =Forecast!E6 -> 2 | F5: =Forecast!F6 -> 3 | G5: =Forecast!G6 -> 4 | H5: =Forecast!H6 -> 5 | I5: =Forecast!I6 -> 6 | J5: =Forecast!J6 -> 7 | K5: =Forecast!K6 -> 8 | ... AM5: =Forecast!AM6 -> 36
A6: UNIT ECONOMICS PER CARD AND PER KIOSK (selected scenario)
A7: Price per card (ex tax) | B7: =Inputs!$H$194 -> 6.99
A8: Host revenue share per card | B8: =B7*Inputs!$H$196 -> 1.7475
A9: Payment fee per card | B9: =B7*Inputs!$H$197+Inputs!$H$198 -> 0.23873
A10: Consumables per card | B10: =Inputs!$H$199 -> 0.3996
A11: Model cost, Totally custom session (live from Model Costs printed-card token cost + intake) | B11: ='Model Costs'!$J$36*Scenarios!$B$10*(1+Inputs!$B$42)+Inputs!$H$202 -> 0.3615345
A12: Model cost per card sold (session mix x cost, x (1 + abandoned sessions)) | B12: =(Inputs!$B$203*Inputs!$H$200+Inputs!$B$204*Inputs!$H$201+Inputs!$B$205*B11)*(1+Inputs!$B$206) -> 0.20381431
A13: Contribution per card (mature) | B13: =B7-B8-B9-B10-B12 -> 4.4003557
A14: Fixed operating cost per kiosk per month (6 lines, incl. service visits) | B14: =Inputs!$H$210+Inputs!$H$211+Inputs!$H$212+Inputs!$H$213+Inputs!$H$214+Inputs!$H$215 -> 262
A15: Cards per kiosk per month (mature) | B15: =Inputs!$H$195*Inputs!$B$209 -> 152
A16: Operating cash per kiosk per month (mature) | B16: =B15*B13-B14 -> 406.85406
A17: Hardware cost per kiosk at the 10-unit quantity (x scenario multiplier) | B17: =Inputs!$B$219*Inputs!$H$217 -> 11970
A18: Depreciation per kiosk per month | B18: =B17/Inputs!$H$216 -> 332.5
A19: Net after depreciation per kiosk per month (mature) | B19: =B16-B18 -> 74.354064
A20: Kiosk payback, months (hardware / operating cash; mature rate) | B20: =IF(B16>0,B17/B16,"Never at this rate") -> 29.420869
A21: Break-even cards per kiosk per day, cash | B21: =IF(B13>0,B14/(Inputs!$B$209*B13),"n/a") -> 1.9585737
A22: Break-even cards per kiosk per day, after depreciation | B22: =IF(B13>0,(B14+B18)/(Inputs!$B$209*B13),"n/a") -> 4.4441683
A24: FLEET BUILD (units deployed by month, driven by the gates)
A25: Target units live (fleet plan, Inputs) | B25: units | D25: =INDEX(Inputs!$B$226:$B$261,D$5) -> 0 | E25: =INDEX(Inputs!$B$226:$B$261,E$5) -> 0 | F25: =INDEX(Inputs!$B$226:$B$261,F$5) -> 0 | G25: =INDEX(Inputs!$B$226:$B$261,G$5) -> 0 | H25: =INDEX(Inputs!$B$226:$B$261,H$5) -> 0 | I25: =INDEX(Inputs!$B$226:$B$261,I$5) -> 0 | J25: =INDEX(Inputs!$B$226:$B$261,J$5) -> 0 | K25: =INDEX(Inputs!$B$226:$B$261,K$5) -> 0 | ... AM25: =INDEX(Inputs!$B$226:$B$261,AM$5) -> 50
